Workbook

Sheet State_Water_Bodies
A1: India Water Quality and Resource Monitoring - Water Bodies Registry
A2: State-wise inventory of monitored reservoirs, ponds, and hydrological network stations (2021-2026)
A4: Year | B4: State | C4: Region | D4: District | E4: Water Body Type | F4: Water Body Name | G4: Water Body ID | H4: Area (Sqkm) | I4: Storage Capacity (T.M.C.) | J4: Monitoring Sites | K4: Source
A5: 2021 | B5: Andhra Pradesh | C5: Rayalaseema | D5: Nandyal | E5: Reservoir (Major) | F5: Srisailam Reservoir | G5: AP-RES-001 | H5: - | I5: 215.81 | J5: 1 | K5: APWRIMS Portal
A6: 2021 | B6: Andhra Pradesh | C6: Rayalaseema | D6: Palnadu | E6: Reservoir (Major) | F6: Nagarjuna Sagar | G6: AP-RES-002 | H6: - | I6: 312.05 | J6: 1 | K6: APWRIMS Portal
A7: 2021 | B7: Andhra Pradesh | C7: Rayalaseema | D7: Sri Potti Sriramulu Nellore | E7: Reservoir (Major) | F7: Somasila Reservoir | G7: AP-RES-003 | H7: - | I7: 78 | J7: 1 | K7: APWRIMS Portal
A8: 2021 | B8: Andhra Pradesh | C8: Rayalaseema | D8: Sri Potti Sriramulu Nellore | E8: Reservoir (Major) | F8: Kandaleru Reservoir | G8: AP-RES-004 | H8: - | I8: 68.03 | J8: 1 | K8: APWRIMS Portal
A9: 2021 | B9: Andhra Pradesh | C9: Rayalaseema | D9: Y.S.R Kadapa | E9: Reservoir (Major) | F9: Brahmamsagar Reservoir | G9: AP-RES-005 | H9: - | I9: 17.74 | J9: 1 | K9: APWRIMS Portal
A10: 2021 | B10: Andhra Pradesh | C10: Coastal Andhra | D10: Alluri Sitharama Raju | E10: Reservoir (Major) | F10: Donkarayi Reservoir | G10: AP-RES-006 | H10: - | I10: 16.51 | J10: 1 | K10: APWRIMS Portal
A11: 2021 | B11: Andhra Pradesh | C11: Rayalaseema | D11: Y.S.R Kadapa | E11: Reservoir (Major) | F11: Gandikota Reservoir | G11: AP-RES-007 | H11: - | I11: 26.85 | J11: 1 | K11: APWRIMS Portal
A12: 2021 | B12: Haryana | C12: North | D12: All Districts | E12: Pond Authority Network | F12: Government Ponds | G12: HR-PND-001 | H12: - | I12: - | J12: 13722 | K12: OneMap Haryana SWIC
A13: 2021 | B13: Haryana | C13: North | D13: All Districts | E13: Pond Authority Network | F13: Private Ponds | G13: HR-PND-002 | H13: - | I13: - | J13: 6139 | K13: OneMap Haryana SWIC
A14: 2021 | B14: Haryana | C14: North | D14: All Districts | E14: Pond Authority Network | F14: Other & Historic Ponds | G14: HR-PND-003 | H14: - | I14: - | J14: 10574 | K14: OneMap Haryana SWIC
A15: 2021 | B15: Odisha | C15: East | D15: State-wide | E15: Groundwater Station Network | F15: CGWB Monitoring Wells | G15: OD-GW-ALL | H15: - | I15: - | J15: 789 | K15: Odisha SWIC Dashboard
A16: 2021 | B16: Odisha | C16: East | D16: State-wide | E16: Surface Station Network | F16: Central River Gauges | G16: OD-SW-ALL | H16: - | I16: - | J16: 205 | K16: Odisha SWIC Dashboard
A17: 2021 | B17: Odisha | C17: East | D17: State-wide | E17: SCADA Systems | F17: Reservoir Automation | G17: OD-SCA-ALL | H17: - | I17: - | J17: 2 | K17: Odisha SWIC Dashboard
A18: 2021 | B18: Uttarakhand | C18: North | D18: State-wide | E18: CPCB Main-stem Stations | F18: River Ganga Stations | G18: UT-GNG-ALL | H18: - | I18: - | J18: 15 | K18: CPCB Dashboard
A19: 2021 | B19: Uttar Pradesh | C19: North | D19: State-wide | E19: CPCB Main-stem Stations | F19: River Ganga Stations | G19: UP-GNG-ALL | H19: - | I19: - | J19: 30 | K19: CPCB Dashboard
A20: 2021 | B20: Bihar | C20: East | D20: State-wide | E20: CPCB Main-stem Stations | F20: River Ganga Stations | G20: BH-GNG-ALL | H20: - | I20: - | J20: 24 | K20: CPCB Dashboard
A21: 2021 | B21: Jharkhand | C21: East | D21: State-wide | E21: CPCB Main-stem Stations | F21: River Ganga Stations | G21: JH-GNG-ALL | H21: - | I21: - | J21: 3 | K21: CPCB Dashboard
A22: 2021 | B22: West Bengal | C22: East | D22: State-wide | E22: CPCB Main-stem Stations | F22: River Ganga Stations | G22: WB-GNG-ALL | H22: - | I22: - | J22: 11 | K22: CPCB Dashboard
A23: 2022 | B23: Andhra Pradesh | C23: Rayalaseema | D23: Nandyal | E23: Reservoir (Major) | F23: Srisailam Reservoir | G23: AP-RES-001 | H23: - | I23: 215.81 | J23: 1 | K23: APWRIMS Portal
A24: 2022 | B24: Andhra Pradesh | C24: Rayalaseema | D24: Palnadu | E24: Reservoir (Major) | F24: Nagarjuna Sagar | G24: AP-RES-002 | H24: - | I24: 312.05 | J24: 1 | K24: APWRIMS Portal
A25: 2022 | B25: Andhra Pradesh | C25: Rayalaseema | D25: Sri Potti Sriramulu Nellore | E25: Reservoir (Major) | F25: Somasila Reservoir | G25: AP-RES-003 | H25: - | I25: 78 | J25: 1 | K25: APWRIMS Portal
A26: 2022 | B26: Andhra Pradesh | C26: Rayalaseema | D26: Sri Potti Sriramulu Nellore | E26: Reservoir (Major) | F26: Kandaleru Reservoir | G26: AP-RES-004 | H26: - | I26: 68.03 | J26: 1 | K26: APWRIMS Portal
A27: 2022 | B27: Andhra Pradesh | C27: Rayalaseema | D27: Y.S.R Kadapa | E27: Reservoir (Major) | F27: Brahmamsagar Reservoir | G27: AP-RES-005 | H27: - | I27: 17.74 | J27: 1 | K27: APWRIMS Portal
A28: 2022 | B28: Andhra Pradesh | C28: Coastal Andhra | D28: Alluri Sitharama Raju | E28: Reservoir (Major) | F28: Donkarayi Reservoir | G28: AP-RES-006 | H28: - | I28: 16.51 | J28: 1 | K28: APWRIMS Portal
A29: 2022 | B29: Andhra Pradesh | C29: Rayalaseema | D29: Y.S.R Kadapa | E29: Reservoir (Major) | F29: Gandikota Reservoir | G29: AP-RES-007 | H29: - | I29: 26.85 | J29: 1 | K29: APWRIMS Portal
A30: 2022 | B30: Haryana | C30: North | D30: All Districts | E30: Pond Authority Network | F30: Government Ponds | G30: HR-PND-001 | H30: - | I30: - | J30: 15162 | K30: OneMap Haryana SWIC
A31: 2022 | B31: Haryana | C31: North | D31: All Districts | E31: Pond Authority Network | F31: Private Ponds | G31: HR-PND-002 | H31: - | I31: - | J31: 6733 | K31: OneMap Haryana SWIC
A32: 2022 | B32: Haryana | C32: North | D32: All Districts | E32: Pond Authority Network | F32: Other & Historic Ponds | G32: HR-PND-003 | H32: - | I32: - | J32: 11634 | K32: OneMap Haryana SWIC
A33: 2022 | B33: Odisha | C33: East | D33: State-wide | E33: Groundwater Station Network | F33: CGWB Monitoring Wells | G33: OD-GW-ALL | H33: - | I33: - | J33: 876 | K33: Odisha SWIC Dashboard
A34: 2022 | B34: Odisha | C34: East | D34: State-wide | E34: Surface Station Network | F34: Central River Gauges | G34: OD-SW-ALL | H34: - | I34: - | J34: 217 | K34: Odisha SWIC Dashboard
A35: 2022 | B35: Odisha | C35: East | D35: State-wide | E35: SCADA Systems | F35: Reservoir Automation | G35: OD-SCA-ALL | H35: - | I35: - | J35: 3 | K35: Odisha SWIC Dashboard
A36: 2022 | B36: Uttarakhand | C36: North | D36: State-wide | E36: CPCB Main-stem Stations | F36: River Ganga Stations | G36: UT-GNG-ALL | H36: - | I36: - | J36: 15 | K36: CPCB Dashboard
A37: 2022 | B37: Uttar Pradesh | C37: North | D37: State-wide | E37: CPCB Main-stem Stations | F37: River Ganga Stations | G37: UP-GNG-ALL | H37: - | I37: - | J37: 33 | K37: CPCB Dashboard
A38: 2022 | B38: Bihar | C38: East | D38: State-wide | E38: CPCB Main-stem Stations | F38: River Ganga Stations | G38: BH-GNG-ALL | H38: - | I38: - | J38: 26 | K38: CPCB Dashboard
A39: 2022 | B39: Jharkhand | C39: East | D39: State-wide | E39: CPCB Main-stem Stations | F39: River Ganga Stations | G39: JH-GNG-ALL | H39: - | I39: - | J39: 3 | K39: CPCB Dashboard
A40: 2022 | B40: West Bengal | C40: East | D40: State-wide | E40: CPCB Main-stem Stations | F40: River Ganga Stations | G40: WB-GNG-ALL | H40: - | I40: - | J40: 12 | K40: CPCB Dashboard
A41: 2023 | B41: Andhra Pradesh | C41: Rayalaseema | D41: Nandyal | E41: Reservoir (Major) | F41: Srisailam Reservoir | G41: AP-RES-001 | H41: - | I41: 215.81 | J41: 1 | K41: APWRIMS Portal
...

Sheet Water_Quality
A1: India Water Quality Monitoring - Ground and Surface Water Sample Analysis
A2: Physical and chemical water quality measurements from CPCB real-time stations and CGWB district monitoring
A4: Year | B4: Monitoring Date | C4: State | D4: District | E4: Water Body Name | F4: Water Body ID | G4: Water Body Type | H4: Parameter | I4: Value | J4: Unit | K4: Standard Limit | L4: Quality Status | M4: Source
A5: 2021 | B5: 2021-08-28 | C5: Bihar | D5: Buxar | E5: River Ganga at Chausa | F5: BH72 | G5: River | H5: pH | I5: 7.28 | J5: SU | K5: 6.5-8.5 | L5: Within Limits | M5: CPCB Dashboard
A6: 2021 | B6: 2021-08-28 | C6: Bihar | D6: Buxar | E6: River Ganga at Chausa | F6: BH72 | G6: River | H6: Dissolved Oxygen (DO) | I6: 4.2 | J6: mg/l | K6: >= 4.0 | L6: Within Limits | M6: CPCB Dashboard
A7: 2021 | B7: 2021-08-28 | C7: Bihar | D7: Buxar | E7: River Ganga at Chausa | F7: BH72 | G7: River | H7: Biochemical Oxygen Demand (BOD) | I7: 3.3 | J7: mg/l | K7: <= 3.0 | L7: Critical Exceedance | M7: CPCB Dashboard
A8: 2021 | B8: 2021-08-28 | C8: Bihar | D8: Buxar | E8: River Ganga at Chausa | F8: BH72 | G8: River | H8: Chemical Oxygen Demand (COD) | I8: 15.72 | J8: mg/l | K8: <= 25.0 | L8: Within Limits | M8: CPCB Dashboard
A9: 2021 | B9: 2020-08-10 | C9: Andhra Pradesh | D9: Y.S.R Kadapa | E9: District Aquifers | F9: AP-GW-001 | G9: Groundwater | H9: Nitrate | I9: 2081.236 | J9: mg/L | K9: <= 45 | L9: Critical Exceedance | M9: CGWB Report
A10: 2021 | B10: 2020-08-10 | C10: Telangana | D10: Nagarkurnool | E10: District Aquifers | F10: TG-GW-001 | G10: Groundwater | H10: Nitrate | I10: 2098.952 | J10: mg/L | K10: <= 45 | L10: Critical Exceedance | M10: CGWB Report
A11: 2021 | B11: 2020-08-10 | C11: Karnataka | D11: Chitradurga | E11: District Aquifers | F11: KA-GW-001 | G11: Groundwater | H11: Nitrate | I11: 1972.735 | J11: mg/L | K11: <= 45 | L11: Critical Exceedance | M11: CGWB Report
A12: 2021 | B12: 2020-08-10 | C12: Rajasthan | D12: Churu | E12: District Aquifers | F12: RJ-GW-001 | G12: Groundwater | H12: Nitrate | I12: 1248.06 | J12: mg/L | K12: <= 45 | L12: Critical Exceedance | M12: CGWB Report
A13: 2021 | B13: 2020-08-10 | C13: West Bengal | D13: Nadia | E13: District Aquifers | F13: WB-GW-001 | G13: Groundwater | H13: Arsenic | I13: 328.877 | J13: ppb | K13: <= 10 | L13: Critical Exceedance | M13: CGWB Report
A14: 2021 | B14: 2020-08-10 | C14: West Bengal | D14: Murshidabad | E14: District Aquifers | F14: WB-GW-002 | G14: Groundwater | H14: Arsenic | I14: 270.447 | J14: ppb | K14: <= 10 | L14: Critical Exceedance | M14: CGWB Report
A15: 2021 | B15: 2020-08-10 | C15: Bihar | D15: Buxar | E15: District Aquifers | F15: BH-GW-001 | G15: Groundwater | H15: Arsenic | I15: 310.539 | J15: ppb | K15: <= 10 | L15: Critical Exceedance | M15: CGWB Report
A16: 2021 | B16: 2020-08-10 | C16: Haryana | D16: Sirsa | E16: District Aquifers | F16: HR-GW-001 | G16: Groundwater | H16: Fluoride | I16: 19.871 | J16: mg/L | K16: <= 1.5 | L16: Critical Exceedance | M16: CGWB Report
... A118: 2026 | B118: 2025-08-10 | C118: Tamil Nadu | D118: Pudukkottai | E118: District Aquifers | F118: TN-GW-001 | G118: Groundwater | H118: Zinc | I118: 58.622 | J118: mg/L | K118: <= 15.0 | L118: Critical Exceedance | M118: CGWB Report

Sheet State_Quality_Summary
A1: India State-wise Water Quality Summary
A2: Consolidated average water chemistry indices and official sample testing performance statistics (2021-2026)
A4: Year | B4: State | C4: Region | D4: Water Body Type | E4: Monitoring Sites | F4: Average pH | G4: Average DO (mg/l) | H4: Average BOD (mg/l) | I4: Average COD (mg/l) | J4: Average TDS (mg/l) | K4: Average Turbidity (NTU) | L4: Good Sites (Tested) | M4: Moderate Sites | N4: Poor Sites (Contaminated) | O4: Critical Sites | P4: Overall Status
A5: 2021 | B5: Andaman & Nicobar Islands | C5: UT | D5: Drinking Water Sources | E5: 9 | F5: 7.08 | G5: 6.96 | H5: 1.24 | I5: 5.65 | J5: 245.55 | K5: 1.77 | L5: 399 | M5: 0 | N5: 1 | O5: 0 | P5: Safe (0.25% Contam.)
A6: 2021 | B6: Andhra Pradesh | C6: South | D6: Drinking Water Sources | E6: 107 | F6: 7.17 | G6: 6.73 | H6: 1.16 | I6: 5.45 | J6: 245.78 | K6: 1.84 | L6: 44706 | M6: 0 | N6: 0 | O6: 0 | P6: Excellent (Zero Lab Contam.)
A7: 2021 | B7: Arunachal Pradesh | C7: North East | D7: Drinking Water Sources | E7: 30 | F7: 7.1 | G7: 6.68 | H7: 1.22 | I7: 5.18 | J7: 248.2 | K7: 1.77 | L7: 18440 | M7: 0 | N7: 0 | O7: 0 | P7: Excellent (Zero Lab Contam.)
A8: 2021 | B8: Assam | C8: North East | D8: Drinking Water Sources | E8: 69 | F8: 7.1 | G8: 6.85 | H8: 1.24 | I8: 5.41 | J8: 243.35 | K8: 1.87 | L8: 41850 | M8: 0 | N8: 329 | O8: 0 | P8: Safe (0.78% Contam.)
A9: 2021 | B9: Bihar | C9: East | D9: Drinking Water Sources | E9: 97 | F9: 7.38 | G9: 5.23 | H9: 2.79 | I9: 11.77 | J9: 133.12 | K9: 174.94 | L9: 34993 | M9: 0 | N9: 7 | O9: 0 | P9: Safe (0.02% Contam.)
A10: 2021 | B10: Chhattisgarh | C10: Central | D10: Drinking Water Sources | E10: 65 | F10: 7.14 | G10: 6.74 | H10: 1.14 | I10: 5.6 | J10: 256.7 | K10: 1.8 | L10: 21092 | M10: 0 | N10: 19 | O10: 0 | P10: Safe (0.09% Contam.)
A11: 2021 | B11: Dadra & Nagar Haveli And Daman & Diu | C11: UT | D11: Drinking Water Sources | E11: 2 | F11: 7.14 | G11: 6.63 | H11: 1.23 | I11: 5.42 | J11: 252.05 | K11: 1.75 | L11: 0 | M11: 0 | N11: 0 | O11: 0 | P11: Excellent (Zero Lab Contam.)
A12: 2021 | B12: Goa | C12: West | D12: Drinking Water Sources | E12: 19 | F12: 7.07 | G12: 6.94 | H12: 1.21 | I12: 5.75 | J12: 244.59 | K12: 1.87 | L12: 466 | M12: 0 | N12: 3 | O12: 0 | P12: Safe (0.64% Contam.)
A13: 2021 | B13: Gujarat | C13: West | D13: Drinking Water Sources | E13: 333 | F13: 7.15 | G13: 6.9 | H13: 1.26 | I13: 5.79 | J13: 255.03 | K13: 1.84 | L13: 80900 | M13: 0 | N13: 276 | O13: 0 | P13: Safe (0.34% Contam.)
A14: 2021 | B14: Haryana | C14: North | D14: Drinking Water Sources | E14: 36 | F14: 7.05 | G14: 6.85 | H14: 1.16 | I14: 5.25 | J14: 254.1 | K14: 1.78 | L14: 11614 | M14: 0 | N14: 1279 | O14: 0 | P14: Poor Quality (9.92%)
A15: 2021 | B15: Himachal Pradesh | C15: North | D15: Drinking Water Sources | E15: 67 | F15: 7.05 | G15: 6.76 | H15: 1.25 | I15: 5.41 | J15: 253.88 | K15: 1.77 | L15: 56912 | M15: 0 | N15: 0 | O15: 0 | P15: Excellent (Zero Lab Contam.)
A16: 2021 | B16: Jammu & Kashmir | C16: North | D16: Drinking Water Sources | E16: 80 | F16: 7.13 | G16: 6.79 | H16: 1.22 | I16: 5.72 | J16: 246.16 | K16: 1.77 | L16: 75661 | M16: 0 | N16: 53 | O16: 0 | P16: Safe (0.07% Contam.)
... A208: 2026 | B208: West Bengal | C208: East | D208: Drinking Water Sources | E208: 241 | F208: 7.1 | G208: 6.8 | H208: 1.2 | I208: 5.4 | J208: 250 | K208: 1.8 | L208: 76977 | M208: 0 | N208: 18268 | O208: 0 | P208: Poor Quality (19.18%)
B209: Grand Total | E209: =SUM(E5:E208) -> 15554 | L209: =SUM(L5:L208) -> 12155170 | N209: =SUM(N5:N208) -> 277018

Sheet State_Intelligence
A1: India Water Resources State Intelligence Profile
A2: Strategic dashboard mapping regional assets, monitoring footprints, and chemical compliance percentiles (2021-2026)
A4: Year | B4: State | C4: Region | D4: Total Water Bodies | E4: Total Ponds | F4: Total Rivers | G4: Total Lakes | H4: Total Reservoirs | I4: Monitoring Sites | J4: Good Quality % | K4: Moderate Quality % | L4: Poor Quality % | M4: Critical Quality % | N4: Overall Water Quality Status
A5: 2021 | B5: Andaman & Nicobar Islands | C5: UT | D5: - | E5: - | F5: - | G5: - | H5: - | I5: 9 | J5: =IF(SUM(State_Quality_Summary!L5,State_Quality_Summary!N5)>0, State_Quality_Summary!L5/SUM(State_Quality_Summary!L5,State_Quality_Summary!N5), 1) -> 0.9975 | K5: 0 | L5: =IF(SUM(State_Quality_Summary!L5,State_Quality_Summary!N5)>0, State_Quality_Summary!N5/SUM(State_Quality_Summary!L5,State_Quality_Summary!N5), 0) -> 0.0025 | M5: 0 | N5: =IF(L5>0.05,"Poor Quality",IF(L5>0.01,"Moderately Safe","Excellent")) -> Excellent
A6: 2021 | B6: Andhra Pradesh | C6: South | D6: 115 | E6: - | F6: 4 | G6: - | H6: 115 | I6: 107 | J6: =IF(SUM(State_Quality_Summary!L6,State_Quality_Summary!N6)>0, State_Quality_Summary!L6/SUM(State_Quality_Summary!L6,State_Quality_Summary!N6), 1) -> 1 | K6: 0 | L6: =IF(SUM(State_Quality_Summary!L6,State_Quality_Summary!N6)>0, State_Quality_Summary!N6/SUM(State_Quality_Summary!L6,State_Quality_Summary!N6), 0) -> 0 | M6: 0 | N6: =IF(L6>0.05,"Poor Quality",IF(L6>0.01,"Moderately Safe","Excellent")) -> Excellent
A7: 2021 | B7: Arunachal Pradesh | C7: North East | D7: - | E7: - | F7: - | G7: - | H7: - | I7: 30 | J7: =IF(SUM(State_Quality_Summary!L7,State_Quality_Summary!N7)>0, State_Quality_Summary!L7/SUM(State_Quality_Summary!L7,State_Quality_Summary!N7), 1) -> 1 | K7: 0 | L7: =IF(SUM(State_Quality_Summary!L7,State_Quality_Summary!N7)>0, State_Quality_Summary!N7/SUM(State_Quality_Summary!L7,State_Quality_Summary!N7), 0) -> 0 | M7: 0 | N7: =IF(L7>0.05,"Poor Quality",IF(L7>0.01,"Moderately Safe","Excellent")) -> Excellent
A8: 2021 | B8: Assam | C8: North East | D8: - | E8: - | F8: - | G8: - | H8: - | I8: 69 | J8: =IF(SUM(State_Quality_Summary!L8,State_Quality_Summary!N8)>0, State_Quality_Summary!L8/SUM(State_Quality_Summary!L8,State_Quality_Summary!N8), 1) -> 0.99219991 | K8: 0 | L8: =IF(SUM(State_Quality_Summary!L8,State_Quality_Summary!N8)>0, State_Quality_Summary!N8/SUM(State_Quality_Summary!L8,State_Quality_Summary!N8), 0) -> 0.0078000901 | M8: 0 | N8: =IF(L8>0.05,"Poor Quality",IF(L8>0.01,"Moderately Safe","Excellent")) -> Excellent
A9: 2021 | B9: Bihar | C9: East | D9: - | E9: - | F9: - | G9: - | H9: - | I9: 97 | J9: =IF(SUM(State_Quality_Summary!L9,State_Quality_Summary!N9)>0, State_Quality_Summary!L9/SUM(State_Quality_Summary!L9,State_Quality_Summary!N9), 1) -> 0.9998 | K9: 0 | L9: =IF(SUM(State_Quality_Summary!L9,State_Quality_Summary!N9)>0, State_Quality_Summary!N9/SUM(State_Quality_Summary!L9,State_Quality_Summary!N9), 0) -> 0.0002 | M9: 0 | N9: =IF(L9>0.05,"Poor Quality",IF(L9>0.01,"Moderately Safe","Excellent")) -> Excellent
A10: 2021 | B10: Chhattisgarh | C10: Central | D10: - | E10: - | F10: - | G10: - | H10: - | I10: 65 | J10: =IF(SUM(State_Quality_Summary!L10,State_Quality_Summary!N10)>0, State_Quality_Summary!L10/SUM(State_Quality_Summary!L10,State_Quality_Summary!N10), 1) -> 0.9991 | K10: 0 | L10: =IF(SUM(State_Quality_Summary!L10,State_Quality_Summary!N10)>0, State_Quality_Summary!N10/SUM(State_Quality_Summary!L10,State_Quality_Summary!N10), 0) -> 0.00090000474 | M10: 0 | N10: =IF(L10>0.05,"Poor Quality",IF(L10>0.01,"Moderately Safe","Excellent")) -> Excellent
A11: 2021 | B11: Dadra & Nagar Haveli And Daman & Diu | C11: UT | D11: - | E11: - | F11: - | G11: - | H11: - | I11: 2 | J11: =IF(SUM(State_Quality_Summary!L11,State_Quality_Summary!N11)>0, State_Quality_Summary!L11/SUM(State_Quality_Summary!L11,State_Quality_Summary!N11), 1) -> 1 | K11: 0 | L11: =IF(SUM(State_Quality_Summary!L11,State_Quality_Summary!N11)>0, State_Quality_Summary!N11/SUM(State_Quality_Summary!L11,State_Quality_Summary!N11), 0) -> 0 | M11: 0 | N11: =IF(L11>0.05,"Poor Quality",IF(L11>0.01,"Moderately Safe","Excellent")) -> Excellent
A12: 2021 | B12: Goa | C12: West | D12: 3 | E12: - | F12: - | G12: - | H12: 3 | I12: 19 | J12: =IF(SUM(State_Quality_Summary!L12,State_Quality_Summary!N12)>0, State_Quality_Summary!L12/SUM(State_Quality_Summary!L12,State_Quality_Summary!N12), 1) -> 0.99360341 | K12: 0 | L12: =IF(SUM(State_Quality_Summary!L12,State_Quality_Summary!N12)>0, State_Quality_Summary!N12/SUM(State_Quality_Summary!L12,State_Quality_Summary!N12), 0) -> 0.0063965885 | M12: 0 | N12: =IF(L12>0.05,"Poor Quality",IF(L12>0.01,"Moderately Safe","Excellent")) -> Excellent
A13: 2021 | B13: Gujarat | C13: West | D13: - | E13: - | F13: - | G13: - | H13: - | I13: 333 | J13: =IF(SUM(State_Quality_Summary!L13,State_Quality_Summary!N13)>0, State_Quality_Summary!L13/SUM(State_Quality_Summary!L13,State_Quality_Summary!N13), 1) -> 0.99659998 | K13: 0 | L13: =IF(SUM(State_Quality_Summary!L13,State_Quality_Summary!N13)>0, State_Quality_Summary!N13/SUM(State_Quality_Summary!L13,State_Quality_Summary!N13), 0) -> 0.0034000197 | M13: 0 | N13: =IF(L13>0.05,"Poor Quality",IF(L13>0.01,"Moderately Safe","Excellent")) -> Excellent
A14: 2021 | B14: Haryana | C14: North | D14: 40822 | E14: 40822 | F14: 1 | G14: - | H14: - | I14: 36 | J14: =IF(SUM(State_Quality_Summary!L14,State_Quality_Summary!N14)>0, State_Quality_Summary!L14/SUM(State_Quality_Summary!L14,State_Quality_Summary!N14), 1) -> 0.90079888 | K14: 0 | L14: =IF(SUM(State_Quality_Summary!L14,State_Quality_Summary!N14)>0, State_Quality_Summary!N14/SUM(State_Quality_Summary!L14,State_Quality_Summary!N14), 0) -> 0.099201117 | M14: 0 | N14: =IF(L14>0.05,"Poor Quality",IF(L14>0.01,"Moderately Safe","Excellent")) -> Poor Quality
A15: 2021 | B15: Himachal Pradesh | C15: North | D15: - | E15: - | F15: - | G15: - | H15: - | I15: 67 | J15: =IF(SUM(State_Quality_Summary!L15,State_Quality_Summary!N15)>0, State_Quality_Summary!L15/SUM(State_Quality_Summary!L15,State_Quality_Summary!N15), 1) -> 1 | K15: 0 | L15: =IF(SUM(State_Quality_Summary!L15,State_Quality_Summary!N15)>0, State_Quality_Summary!N15/SUM(State_Quality_Summary!L15,State_Quality_Summary!N15), 0) -> 0 | M15: 0 | N15: =IF(L15>0.05,"Poor Quality",IF(L15>0.01,"Moderately Safe","Excellent")) -> Excellent
A16: 2021 | B16: Jammu & Kashmir | C16: North | D16: - | E16: - | F16: - | G16: - | H16: - | I16: 80 | J16: =IF(SUM(State_Quality_Summary!L16,State_Quality_Summary!N16)>0, State_Quality_Summary!L16/SUM(State_Quality_Summary!L16,State_Quality_Summary!N16), 1) -> 0.9993 | K16: 0 | L16: =IF(SUM(State_Quality_Summary!L16,State_Quality_Summary!N16)>0, State_Quality_Summary!N16/SUM(State_Quality_Summary!L16,State_Quality_Summary!N16), 0) -> 0.00070000264 | M16: 0 | N16: =IF(L16>0.05,"Poor Quality",IF(L16>0.01,"Moderately Safe","Excellent")) -> Excellent
A17: 2021 | B17: Jharkhand | C17: East | D17: - | E17: - | F17: - | G17: - | H17: - | I17: 31 | J17: =IF(SUM(State_Quality_Summary!L17,State_Quality_Summary!N17)>0, State_Quality_Summary!L17/SUM(State_Quality_Summary!L17,State_Quality_Summary!N17), 1) -> 0.9998 | K17: 0 | L17: =IF(SUM(State_Quality_Summary!L17,State_Quality_Summary!N17)>0, State_Quality_Summary!N17/SUM(State_Quality_Summary!L17,State_Quality_Summary!N17), 0) -> 0.0002 | M17: 0 | N17: =IF(L17>0.05,"Poor Quality",IF(L17>0.01,"Moderately Safe","Excellent")) -> Excellent
A18: 2021 | B18: Karnataka | C18: South | D18: 11 | E18: - | F18: 1 | G18: - | H18: 11 | I18: 83 | J18: =IF(SUM(State_Quality_Summary!L18,State_Quality_Summary!N18)>0, State_Quality_Summary!L18/SUM(State_Quality_Summary!L18,State_Quality_Summary!N18), 1) -> 0.95510001 | K18: 0 | L18: =IF(SUM(State_Quality_Summary!L18,State_Quality_Summary!N18)>0, State_Quality_Summary!N18/SUM(State_Quality_Summary!L18,State_Quality_Summary!N18), 0) -> 0.044899992 | M18: 0 | N18: =IF(L18>0.05,"Poor Quality",IF(L18>0.01,"Moderately Safe","Excellent")) -> Moderately Safe
A19: 2021 | B19: Kerala | C19: South | D19: - | E19: - | F19: - | G19: - | H19: - | I19: 79 | J19: =IF(SUM(State_Quality_Summary!L19,State_Quality_Summary!N19)>0, State_Quality_Summary!L19/SUM(State_Quality_Summary!L19,State_Quality_Summary!N19), 1) -> 0.91419966 | K19: 0 | L19: =IF(SUM(State_Quality_Summary!L19,State_Quality_Summary!N19)>0, State_Quality_Summary!N19/SUM(State_Quality_Summary!L19,State_Quality_Summary!N19), 0) -> 0.085800343 | M19: 0 | N19: =IF(L19>0.05,"Poor Quality",IF(L19>0.01,"Moderately Safe","Excellent")) -> Poor Quality
A20: 2021 | B20: Ladakh | C20: UT | D20: - | E20: - | F20: - | G20: - | H20: - | I20: 7 | J20: =IF(SUM(State_Quality_Summary!L20,State_Quality_Summary!N20)>0, State_Quality_Summary!L20/SUM(State_Quality_Summary!L20,State_Quality_Summary!N20), 1) -> 0.97690531 | K20: 0 | L20: =IF(SUM(State_Quality_Summary!L20,State_Quality_Summary!N20)>0, State_Quality_Summary!N20/SUM(State_Quality_Summary!L20,State_Quality_Summary!N20), 0) -> 0.023094688 | M20: 0 | N20: =IF(L20>0.05,"Poor Quality",IF(L20>0.01,"Moderately Safe","Excellent")) -> Moderately Safe
A21: 2021 | B21: Lakshadweep | C21: UT | D21: - | E21: - | F21: - | G21: - | H21: - | I21: 7 | J21: =IF(SUM(State_Quality_Summary!L21,State_Quality_Summary!N21)>0, State_Quality_Summary!L21/SUM(State_Quality_Summary!L21,State_Quality_Summary!N21), 1) -> 0.9992 | K21: 0 | L21: =IF(SUM(State_Quality_Summary!L21,State_Quality_Summary!N21)>0, State_Quality_Summary!N21/SUM(State_Quality_Summary!L21,State_Quality_Summary!N21), 0) -> 0.0008 | M21: 0 | N21: =IF(L21>0.05,"Poor Quality",IF(L21>0.01,"Moderately Safe","Excellent")) -> Excellent
A22: 2021 | B22: Madhya Pradesh | C22: Central | D22: - | E22: - | F22: - | G22: - | H22: - | I22: 147 | J22: =IF(SUM(State_Quality_Summary!L22,State_Quality_Summary!N22)>0, State_Quality_Summary!L22/SUM(State_Quality_Summary!L22,State_Quality_Summary!N22), 1) -> 0.9997 | K22: 0 | L22: =IF(SUM(State_Quality_Summary!L22,State_Quality_Summary!N22)>0, State_Quality_Summary!N22/SUM(State_Quality_Summary!L22,State_Quality_Summary!N22), 0) -> 0.00029999927 | M22: 0 | N22: =IF(L22>0.05,"Poor Quality",IF(L22>0.01,"Moderately Safe","Excellent")) -> Excellent
A23: 2021 | B23: Maharashtra | C23: West | D23: 30 | E23: - | F23: 1 | G23: - | H23: 30 | I23: 181 | J23: =IF(SUM(State_Quality_Summary!L23,State_Quality_Summary!N23)>0, State_Quality_Summary!L23/SUM(State_Quality_Summary!L23,State_Quality_Summary!N23), 1) -> 0.95240017 | K23: 0 | L23: =IF(SUM(State_Quality_Summary!L23,State_Quality_Summary!N23)>0, State_Quality_Summary!N23/SUM(State_Quality_Summary!L23,State_Quality_Summary!N23), 0) -> 0.047599833 | M23: 0 | N23: =IF(L23>0.05,"Poor Quality",IF(L23>0.01,"Moderately Safe","Excellent")) -> Moderately Safe
A24: 2021 | B24: Manipur | C24: North East | D24: - | E24: - | F24: - | G24: - | H24: - | I24: 11 | J24: =IF(SUM(State_Quality_Summary!L24,State_Quality_Summary!N24)>0, State_Quality_Summary!L24/SUM(State_Quality_Summary!L24,State_Quality_Summary!N24), 1) -> 1 | K24: 0 | L24: =IF(SUM(State_Quality_Summary!L24,State_Quality_Summary!N24)>0, State_Quality_Summary!N24/SUM(State_Quality_Summary!L24,State_Quality_Summary!N24), 0) -> 0 | M24: 0 | N24: =IF(L24>0.05,"Poor Quality",IF(L24>0.01,"Moderately Safe","Excellent")) -> Excellent
A25: 2021 | B25: Meghalaya | C25: North East | D25: - | E25: - | F25: - | G25: - | H25: - | I25: 24 | J25: =IF(SUM(State_Quality_Summary!L25,State_Quality_Summary!N25)>0, State_Quality_Summary!L25/SUM(State_Quality_Summary!L25,State_Quality_Summary!N25), 1) -> 0.995 | K25: 0 | L25: =IF(SUM(State_Quality_Summary!L25,State_Quality_Summary!N25)>0, State_Quality_Summary!N25/SUM(State_Quality_Summary!L25,State_Quality_Summary!N25), 0) -> 0.005 | M25: 0 | N25: =IF(L25>0.05,"Poor Quality",IF(L25>0.01,"Moderately Safe","Excellent")) -> Excellent
A26: 2021 | B26: Mizoram | C26: North East | D26: - | E26: - | F26: - | G26: - | H26: - | I26: 22 | J26: =IF(SUM(State_Quality_Summary!L26,State_Quality_Summary!N26)>0, State_Quality_Summary!L26/SUM(State_Quality_Summary!L26,State_Quality_Summary!N26), 1) -> 0.94758339 | K26: 0 | L26: =IF(SUM(State_Quality_Summary!L26,State_Quality_Summary!N26)>0, State_Quality_Summary!N26/SUM(State_Quality_Summary!L26,State_Quality_Summary!N26), 0) -> 0.05241661 | M26: 0 | N26: =IF(L26>0.05,"Poor Quality",IF(L26>0.01,"Moderately Safe","Excellent")) -> Poor Quality
A27: 2021 | B27: Nagaland | C27: North East | D27: - | E27: - | F27: - | G27: - | H27: - | I27: 10 | J27: =IF(SUM(State_Quality_Summary!L27,State_Quality_Summary!N27)>0, State_Quality_Summary!L27/SUM(State_Quality_Summary!L27,State_Quality_Summary!N27), 1) -> 1 | K27: 0 | L27: =IF(SUM(State_Quality_Summary!L27,State_Quality_Summary!N27)>0, State_Quality_Summary!N27/SUM(State_Quality_Summary!L27,State_Quality_Summary!N27), 0) -> 0 | M27: 0 | N27: =IF(L27>0.05,"Poor Quality",IF(L27>0.01,"Moderately Safe","Excellent")) -> Excellent
A28: 2021 | B28: Odisha | C28: East | D28: 1357 | E28: - | F28: 268 | G28: - | H28: 3 | I28: 124 | J28: =IF(SUM(State_Quality_Summary!L28,State_Quality_Summary!N28)>0, State_Quality_Summary!L28/SUM(State_Quality_Summary!L28,State_Quality_Summary!N28), 1) -> 0.99009997 | K28: 0 | L28: =IF(SUM(State_Quality_Summary!L28,State_Quality_Summary!N28)>0, State_Quality_Summary!N28/SUM(State_Quality_Summary!L28,State_Quality_Summary!N28), 0) -> 0.0099000338 | M28: 0 | N28: =IF(L28>0.05,"Poor Quality",IF(L28>0.01,"Moderately Safe","Excellent")) -> Excellent
A29: 2021 | B29: Puducherry | C29: UT | D29: - | E29: - | F29: - | G29: - | H29: - | I29: 2 | J29: =IF(SUM(State_Quality_Summary!L29,State_Quality_Summary!N29)>0, State_Quality_Summary!L29/SUM(State_Quality_Summary!L29,State_Quality_Summary!N29), 1) -> 1 | K29: 0 | L29: =IF(SUM(State_Quality_Summary!L29,State_Quality_Summary!N29)>0, State_Quality_Summary!N29/SUM(State_Quality_Summary!L29,State_Quality_Summary!N29), 0) -> 0 | M29: 0 | N29: =IF(L29>0.05,"Poor Quality",IF(L29>0.01,"Moderately Safe","Excellent")) -> Excellent
A30: 2021 | B30: Punjab | C30: North | D30: - | E30: - | F30: - | G30: - | H30: - | I30: 27 | J30: =IF(SUM(State_Quality_Summary!L30,State_Quality_Summary!N30)>0, State_Quality_Summary!L30/SUM(State_Quality_Summary!L30,State_Quality_Summary!N30), 1) -> 0.98790023 | K30: 0 | L30: =IF(SUM(State_Quality_Summary!L30,State_Quality_Summary!N30)>0, State_Quality_Summary!N30/SUM(State_Quality_Summary!L30,State_Quality_Summary!N30), 0) -> 0.012099766 | M30: 0 | N30: =IF(L30>0.05,"Poor Quality",IF(L30>0.01,"Moderately Safe","Excellent")) -> Moderately Safe
A31: 2021 | B31: Rajasthan | C31: West | D31: - | E31: - | F31: - | G31: - | H31: - | I31: 64 | J31: =IF(SUM(State_Quality_Summary!L31,State_Quality_Summary!N31)>0, State_Quality_Summary!L31/SUM(State_Quality_Summary!L31,State_Quality_Summary!N31), 1) -> 0.88829344 | K31: 0 | L31: =IF(SUM(State_Quality_Summary!L31,State_Quality_Summary!N31)>0, State_Quality_Summary!N31/SUM(State_Quality_Summary!L31,State_Quality_Summary!N31), 0) -> 0.11170656 | M31: 0 | N31: =IF(L31>0.05,"Poor Quality",IF(L31>0.01,"Moderately Safe","Excellent")) -> Poor Quality
A32: 2021 | B32: Sikkim | C32: North East | D32: - | E32: - | F32: - | G32: - | H32: - | I32: 2 | J32: =IF(SUM(State_Quality_Summary!L32,State_Quality_Summary!N32)>0, State_Quality_Summary!L32/SUM(State_Quality_Summary!L32,State_Quality_Summary!N32), 1) -> 0.5 | K32: 0 | L32: =IF(SUM(State_Quality_Summary!L32,State_Quality_Summary!N32)>0, State_Quality_Summary!N32/SUM(State_Quality_Summary!L32,State_Quality_Summary!N32), 0) -> 0.5 | M32: 0 | N32: =IF(L32>0.05,"Poor Quality",IF(L32>0.01,"Moderately Safe","Excellent")) -> Poor Quality
A33: 2021 | B33: Tamil Nadu | C33: South | D33: - | E33: - | F33: - | G33: - | H33: - | I33: 90 | J33: =IF(SUM(State_Quality_Summary!L33,State_Quality_Summary!N33)>0, State_Quality_Summary!L33/SUM(State_Quality_Summary!L33,State_Quality_Summary!N33), 1) -> 0.9998 | K33: 0 | L33: =IF(SUM(State_Quality_Summary!L33,State_Quality_Summary!N33)>0, State_Quality_Summary!N33/SUM(State_Quality_Summary!L33,State_Quality_Summary!N33), 0) -> 0.0002 | M33: 0 | N33: =IF(L33>0.05,"Poor Quality",IF(L33>0.01,"Moderately Safe","Excellent")) -> Excellent
A34: 2021 | B34: Telangana | C34: South | D34: - | E34: - | F34: - | G34: - | H34: - | I34: 95 | J34: =IF(SUM(State_Quality_Summary!L34,State_Quality_Summary!N34)>0, State_Quality_Summary!L34/SUM(State_Quality_Summary!L34,State_Quality_Summary!N34), 1) -> 1 | K34: 0 | L34: =IF(SUM(State_Quality_Summary!L34,State_Quality_Summary!N34)>0, State_Quality_Summary!N34/SUM(State_Quality_Summary!L34,State_Quality_Summary!N34), 0) -> 0 | M34: 0 | N34: =IF(L34>0.05,"Poor Quality",IF(L34>0.01,"Moderately Safe","Excellent")) -> Excellent
A35: 2021 | B35: Tripura | C35: North East | D35: - | E35: - | F35: - | G35: - | H35: - | I35: 17 | J35: =IF(SUM(State_Quality_Summary!L35,State_Quality_Summary!N35)>0, State_Quality_Summary!L35/SUM(State_Quality_Summary!L35,State_Quality_Summary!N35), 1) -> 0.99889998 | K35: 0 | L35: =IF(SUM(State_Quality_Summary!L35,State_Quality_Summary!N35)>0, State_Quality_Summary!N35/SUM(State_Quality_Summary!L35,State_Quality_Summary!N35), 0) -> 0.0011000236 | M35: 0 | N35: =IF(L35>0.05,"Poor Quality",IF(L35>0.01,"Moderately Safe","Excellent")) -> Excellent
A36: 2021 | B36: Uttar Pradesh | C36: North | D36: 22 | E36: - | F36: 8 | G36: - | H36: 14 | I36: 113 | J36: =IF(SUM(State_Quality_Summary!L36,State_Quality_Summary!N36)>0, State_Quality_Summary!L36/SUM(State_Quality_Summary!L36,State_Quality_Summary!N36), 1) -> 0.99169997 | K36: 0 | L36: =IF(SUM(State_Quality_Summary!L36,State_Quality_Summary!N36)>0, State_Quality_Summary!N36/SUM(State_Quality_Summary!L36,State_Quality_Summary!N36), 0) -> 0.0083000276 | M36: 0 | N36: =IF(L36>0.05,"Poor Quality",IF(L36>0.01,"Moderately Safe","Excellent")) -> Excellent
A37: 2021 | B37: Uttarakhand | C37: North | D37: - | E37: - | F37: - | G37: - | H37: - | I37: 23 | J37: =IF(SUM(State_Quality_Summary!L37,State_Quality_Summary!N37)>0, State_Quality_Summary!L37/SUM(State_Quality_Summary!L37,State_Quality_Summary!N37), 1) -> 0.98879995 | K37: 0 | L37: =IF(SUM(State_Quality_Summary!L37,State_Quality_Summary!N37)>0, State_Quality_Summary!N37/SUM(State_Quality_Summary!L37,State_Quality_Summary!N37), 0) -> 0.011200051 | M37: 0 | N37: =IF(L37>0.05,"Poor Quality",IF(L37>0.01,"Moderately Safe","Excellent")) -> Moderately Safe
A38: 2021 | B38: West Bengal | C38: East | D38: - | E38: - | F38: - | G38: - | H38: - | I38: 199 | J38: =IF(SUM(State_Quality_Summary!L38,State_Quality_Summary!N38)>0, State_Quality_Summary!L38/SUM(State_Quality_Summary!L38,State_Quality_Summary!N38), 1) -> 0.77949797 | K38: 0 | L38: =IF(SUM(State_Quality_Summary!L38,State_Quality_Summary!N38)>0, State_Quality_Summary!N38/SUM(State_Quality_Summary!L38,State_Quality_Summary!N38), 0) -> 0.22050203 | M38: 0 | N38: =IF(L38>0.05,"Poor Quality",IF(L38>0.01,"Moderately Safe","Excellent")) -> Poor Quality
A39: 2022 | B39: Andaman & Nicobar Islands | C39: UT | D39: - | E39: - | F39: - | G39: - | H39: - | I39: 9 | J39: =IF(SUM(State_Quality_Summary!L39,State_Quality_Summary!N39)>0, State_Quality_Summary!L39/SUM(State_Quality_Summary!L39,State_Quality_Summary!N39), 1) -> 0.9975 | K39: 0 | L39: =IF(SUM(State_Quality_Summary!L39,State_Quality_Summary!N39)>0, State_Quality_Summary!N39/SUM(State_Quality_Summary!L39,State_Quality_Summary!N39), 0) -> 0.0025 | M39: 0 | N39: =IF(L39>0.05,"Poor Quality",IF(L39>0.01,"Moderately Safe","Excellent")) -> Excellent
A40: 2022 | B40: Andhra Pradesh | C40: South | D40: 115 | E40: - | F40: 4 | G40: - | H40: 115 | I40: 120 | J40: =IF(SUM(State_Quality_Summary!L40,State_Quality_Summary!N40)>0, State_Quality_Summary!L40/SUM(State_Quality_Summary!L40,State_Quality_Summary!N40), 1) -> 1 | K40: 0 | L40: =IF(SUM(State_Quality_Summary!L40,State_Quality_Summary!N40)>0, State_Quality_Summary!N40/SUM(State_Quality_Summary!L40,State_Quality_Summary!N40), 0) -> 0 | M40: 0 | N40: =IF(L40>0.05,"Poor Quality",IF(L40>0.01,"Moderately Safe","Excellent")) -> Excellent
A41: 2022 | B41: Arunachal Pradesh | C41: North East | D41: - | E41: - | F41: - | G41: - | H41: - | I41: 33 | J41: =IF(SUM(State_Quality_Summary!L41,State_Quality_Summary!N41)>0, State_Quality_Summary!L41/SUM(State_Quality_Summary!L41,State_Quality_Summary!N41), 1) -> 1 | K41: 0 | L41: =IF(SUM(State_Quality_Summary!L41,State_Quality_Summary!N41)>0, State_Quality_Summary!N41/SUM(State_Quality_Summary!L41,State_Quality_Summary!N41), 0) -> 0 | M41: 0 | N41: =IF(L41>0.05,"Poor Quality",IF(L41>0.01,"Moderately Safe","Excellent")) -> Excellent
...

Sheet Reference_Standards
A1: Bureau of Indian Standards (BIS) Water Quality Reference Criteria
A2: Mandatory limits and thresholds for drinking water parameters checked against IS 10500:2012
A4: Parameter | B4: Unit | C4: Minimum Limit | D4: Maximum Limit | E4: Quality Category | F4: Standard/Guideline | G4: Source
A5: pH | B5: SU | C5: 6.5 | D5: 8.5 | E5: Physicochemical | F5: BIS IS 10500:2012 | G5: Bureau of Indian Standards
A6: Fluoride | B6: mg/L | C6: 0 | D6: 1.5 | E6: Chemical Contaminant | F6: BIS IS 10500:2012 Permissible Limit | G6: CGWB Report
A7: Nitrate | B7: mg/L | C7: 0 | D7: 45 | E7: Chemical Contaminant | F7: BIS IS 10500:2012 Acceptable Limit | G7: CGWB Report
A8: Iron | B8: mg/L | C8: 0 | D8: 1 | E8: Chemical Contaminant | F8: BIS IS 10500:2012 Permissible Limit | G8: CGWB Report
A9: Arsenic | B9: ppb | C9: 0 | D9: 10 | E9: Toxic Heavy Metal | F9: BIS IS 10500:2012 Safe Limit | G9: CGWB Report
A10: Uranium | B10: ppb | C10: 0 | D10: 30 | E10: Radiological/Toxic Heavy Metal | F10: BIS IS 10500:2012 Acceptable Limit | G10: CGWB Report
A11: Manganese | B11: mg/L | C11: 0 | D11: 0.3 | E11: Chemical Contaminant | F11: BIS IS 10500:2012 Permissible Limit | G11: CGWB Report
A12: Lead | B12: mg/L | C12: 0 | D12: 0.01 | E12: Toxic Heavy Metal | F12: BIS IS 10500:2012 Safe Limit | G12: CGWB Report
A13: Zinc | B13: mg/L | C13: 0 | D13: 15 | E13: Chemical Contaminant | F13: BIS IS 10500:2012 Permissible Limit | G13: CGWB Report
A14: Salinity (EC) | B14: µS/cm | C14: 0 | D14: 3000 | E14: Physicochemical Index | F14: BIS IS 10500:2012 Desirable Limit | G14: CGWB Report
A15: Dissolved Oxygen (DO) | B15: mg/L | C15: 4 | D15: - | E15: Organic Health Index | F15: CPCB Class B River Standards | G15: CPCB Guidelines
A16: Biochemical Oxygen Demand (BOD) | B16: mg/L | C16: 0 | D16: 3 | E16: Organic Pollution Index | F16: CPCB Class B River Standards | G16: CPCB Guidelines
A17: Chemical Oxygen Demand (COD) | B17: mg/L | C17: 0 | D17: 25 | E17: Organic Pollution Index | F17: BIS Effluent Discharge Standards | G17: CPCB Guidelines

Sheet Source_Metadata
A1: Water Informatics Data Source Registries and Metadata
A2: Comprehensive documentation of integrated central and state data repositories
A4: Dataset Name | B4: Source Organization | C4: Source Reference | D4: Year | E4: Geographic Level | F4: State Coverage | G4: District Coverage | H4: Data Collection Method | I4: Notes
A5: CGWB Ground Water Quality Reports | B5: Central Ground Water Board | C5: Ministry of Jal Shakti, Government of India | D5: 2024 & 2025 | E5: District-wise | F5: All India States | G5: 755 Districts | H5: Manual Well Samples (15,259 locations) | I5: Covers 9 specific chemical contaminants & heavy metals checked against BIS Limits.
A6: JJM WQMIS Drinking Water Testing | B6: Department of Drinking Water & Sanitation | C6: National Water Quality Management Info System (DDWS) | D6: 2026-2027 | E6: State-wise | F6: All India States | G6: National Level | H6: Laboratory (2,850 labs) and Field Testing Kits | I6: Includes testing status of over 2.7 million samples and 4.7 million FTK tests.
A7: APWRIMS Reservoir Storage Summary | B7: Andhra Pradesh Water Resources Department | C7: APWRIMS Dashboard, Andhra Pradesh | D7: 2025 & 2026 | E7: District-wise | F7: Andhra Pradesh | G7: All AP Districts | H7: Real-time automated level telemetries (RTDAS) | I7: Includes hourly flow calculations for Major and Medium dams in Godavari, Krishna, Pennar basins.
A8: OneMap Haryana SWIC Database | B8: Haryana Space Applications Centre (HARSAC) | C8: HARSAC & Pond Authority, Haryana | D8: 2021 & 2026 | E8: Village-wise | F8: Haryana | G8: All Haryana Districts | H8: GIS and satellite classification (Kharif, Ponds) | I8: Maps spatial layouts of 40,822 state ponds and working piezometric well levels.
A9: CPCB River Ganga Main Stem PRS | B9: Central Pollution Control Board | C9: Namami Gange Project Status / PIB Release | D9: 2018 & 2025 | E9: River Stretch | F9: 5 Ganga States | G9: State boundaries | H9: Manual Grab Samples (112 CPCB stations) | I9: Monitors BOD, COD, and DO levels on river stretches, tracking pollution reduction progress.
A10: Karnataka Water Resources System | B10: Karnataka Water Resources Department | C10: KWRIS Geoportal (ACIWRM / KSWIC) | D10: 2025 & 2026 | E10: River Basin & district | F10: Karnataka | G10: All Karnataka Districts | H10: Real-time automated telemetry and satellite tracking | I10: Integrates daily upstream Cauvery basin storages, rainfall, and soil moistures.
